# promise的API



[TOC]



### 构造函数

**promise(executor){}**

**resolve函数**内部定义成功时调用的函数value=>{}

**reject函数**内部定义失败时调用的函数reason=>{}

`executor`会在promise内部立即执行，是一个同步调用，异步操作会在执行器中执行

### then()方法

`then()`方法：`promise.prototype.then`

`(onResolve,onRejected)=>{}`

其中then方法里面的`onResolve`函数表示成功的回调函数`(value)=>{}`

`onRejected`函数表示失败的回调函数`(reason)=>{}`

**这两个回调函数返回的都是一个新的promise对象**

### catch()方法

`catch()`方法也是指定回调函数的，但是它只能指定失败的回调

`reason=>{}`

### resolve()方法

`Promise.resolve(value)`

其中`value`是成功的数据或者是一个promise对象

```
  // promise的resolve方法
  let p1=Promise.resolve('hello')
  console.log(p1)
  // promise{state:fulfilled,result:'hello'}
```

如果传入的是一个非promise类型的对象或者是基本类型，则返回的是成功的状态，而且返回的值是传入的数据本身；

**如果传入的是一个promise对象，则传入的promise对象返回的结果决定了`resolve()`方法返回的结果**

```
  // resolve方法传入一个promise对象
  let p2=Promise.resolve(new Promise((resolve,reject)=>{
    reject('err')
  }))
  console.log(p2)
  //p2{state:'rejected',result:'err'}
  // 报错
```

在没有对失败的情况去做处理，比如调用then()或者catch()对失败进行处理时，浏览器会进行报错

```
 //处理报错(处理失败的结果)
  p2.catch(reason=>{
    console.log(reason)//err
  })
```

### reject()方法

`Promise.reject(reason)`

```
  // reject方法
  let p3=Promise.reject('error')
  console.log(p3)
  // p3{state:'rejected',result:'error'}
```

**reject方法不管传入的是否是一个promise对象，返回的结果都是失败**

```
 let p4=Promise.reject(new Promise((resolve,reject)=>{
    resolve('resolved!!!')
  }))
  console.log(p4)
  //p4{state:'rejected',result:Promise{state:'fulfilled',result:'resolved!!!'}}
```

### all()方法

`promise.all(proimses)`

传入的参数是一个promise的数组，返回的是一个promise对象，`all()`方法返回的状态取决于promises数组的结果，只有所有promise都成功才算成功，只要一个promise失败了就算失败。

```
// all()方法
  let a1=new Promise((resolve,reject)=>{
    resolve("ok")
  })
  let a2=Promise.resolve('success')
  let a3=Promise.resolve('hello')
  let a4=Promise.resolve('world')
  const result=Promise.all([a1,a2,a3,a4])
  console.log(result)
  // Promise {<pending>}[[Prototype]]: Promise[[PromiseState]]: "fulfilled"[[PromiseResult]]: Array(4)0: "ok"1: "success"2: "hello"3: "world"length: 4[[Prototype]]: Array(0)
```

成功时返回的结果中的数组是`result:后面加上数组中各个promise的成功返回结果的数组`

```
    let a1 = new Promise((resolve, reject) => {
      resolve("ok");
    });
    let a2 = Promise.resolve("success");
    let a3 = Promise.resolve("hello");
    let a4 = Promise.resolve("world");
    let a5 = Promise.reject("error");
    const result = Promise.all([a1, a2, a3, a4, a5]);
    console.log(result);
    // Promise {<pending>}
    // [[Prototype]]: Promise
    // [[PromiseState]]: "rejected"
    // [[PromiseResult]]: "error
```

失败时返回的结果就是数组中失败的那个promise的结果，如果数组中有多个失败结果，则返回的结果是第一个失败的结果



