# 回调地狱以及解决回调地狱



[TOC]

### 回调函数

把函数当作一个参数传递，并且函数不会立即执行，只会在特定的时间执行，这样的函数叫做回调函数，在`setTimeout`和`Ajax`中会用到。

```
setTimeout(function(){ //这个function()就是回调函数，它只有在1秒后才会执行 
    console.log('执行了回调函数'); 
},1000)
```



### 回调地狱

如果在回调函数中再传入一个函数，层层嵌套就形成了回调地狱。

比如在发送多个Ajax请求时，第二个请求需要第一个的结果中的值作为参数，第三个请求需要第二个结果中的值作为参数。。。

层层嵌套的回调就是回调地狱

```
//有多个异步任务，要求需要同时拿到所有异步任务的结果，下边就是用回调地狱
$.get("url", (res1) => {
    conosle.log(res1)
    $.get("url+res1", (res2) => {
        conosle.log(res2)
        $.get("url+res2", (res3) => {
            conosle.log(res3)
            $.get("url+res3", (res4) => {
                conosle.log(res4)
            })
        })
    })
})
```

或者是简单的回调函数层层嵌套

```
setTimeout(function () {  //第一层
            console.log(111);
            setTimeout(function () {  //第二程
                console.log(222);
                setTimeout(function () {   //第三层
                    console.log(333);
                }, 1000)
            }, 2000)
        }, 3000)
```

回调地狱会造成代码可复用性不强，可阅读性差，可维护性(迭代性差)，扩展性差等等问题。

### Pomise

Promise，中文翻译过来就是'承诺'，意思是在未来某一个时间点承诺返回数据给你。它是js中的一个原生对象，是一种异步编程的解决方案，可以替换掉传统的回调函数解决方案。

**Promise的本质不是控制异步代码的执行顺序，异步代码的执行顺序是无法控制，而是控制异步代码结果的处理顺序**

**promise本身只是一个容器,真正异步的是它的两个回调resolve()和reject()**

1. promise对象有三个状态：`pending`（进行中），`fulfilled`（已成功），`rejected`（已失败）

2. `Promise`对象的状态改变， 只有两种可能：

   **a**. 从`pending`变为`fulfilled` , 此时应该执行 `resolve()`

   **b**. 从`pending`变为`rejected` , 此时应该执行 `reject()`

3. `promise`在创建对象的时候,里面的代码会立即执行.

   **a**.` promise`创建时，里面的代码还是异步无序操作

   **b**. `promise`的原理是，利用`then`方法将异步操作的结果，按照顺序执行，`catch`方法用来接收处理失败时相应的数据

   **总结： 不要在创建promise的时候去处理异步操作结果，而应该通过 then() 方法来处理**

4.`promise`解决回调地狱的原理：在`then()`方法中返回一个`promise`对象

**在上一个promise的then中返回下一个promise**

```
//1.封装一个函数 ：  根据文件名生成  文件读取的promise
function getPromise(fileName) {
    let p = new Promise((resolve, reject) => {
        //读文件
        fs.readFile(`./data/${fileName}.txt`, 'utf-8', (err, data) => {
            if (err == null) {
                //成功
                resolve(data);
            } else {
                //失败
                reject(err);
            }
        });
    });
    return p;
};

//2.解决需求： 要先读a, 读完a后读b, 读完b后读c.

//开始读取a
getPromise('a').then((data)=>{
    console.log(data);
    //继续读取b
    return getPromise('b');
}).then((data)=>{
    console.log(data);
    //继续读取c
    return getPromise('c');
}).then((data)=>{
    console.log(data);
}).catch((err)=>{
    //以上三个异步操作，只要有任何一个出错，都会执行err
    console.log(err);
});
```

### async/await

如果过多的使用`then()`也会出现新的流程问题，所以在ES2017推出了`async`和`await`

- 一句话概括： async函数相当于是promise异步函数的另一种`高级写法`
- async语法如下

1. 函数前面使用`async`修饰
2. 函数内部，promise操作使用`await`修饰

-   `await` 后面`是promise对象`, 左侧的返回值就是这个promise对象的then方法中的结果
复制代码
-   `await`必须要写在`async`修饰的函数中，不能单独使用，否则程序会报错

```
const fs = require("fs");

/* 
promise实例对象的catch方法 ： 用于捕获异步操作的错误信息
*/


//1.封装一个函数 ：  根据文件名生成  文件读取的promise
function getPromise(fileName) {
    let p = new Promise((resolve, reject) => {
        //读文件
        fs.readFile(`./data/${fileName}.txt`, 'utf-8', (err, data) => {
            if (err == null) {
                //成功
                resolve(data);
            } else {
                //失败
                reject(err);
            }
        });
    });
    return p;
};

//2.解决需求： 要先读a, 读完a后读b, 读完b后读c.

// async和await异步函数 :  这两个关键字只能用于函数, 所以用的时候一定要放在函数里面用

/* 
async关键字:  修饰函数。  表示这个函数内部有异步操作。 
await关键字:  等待异步执行完毕。
    (1)await只能用于被async修饰的函数中。  
        只有当await后面的异步操作执行完毕后,才会继续执行后面代码
    (2)await 后面 只能是promise对象
*/

const readFile = async () => {
    
    let data1 = await getPromise('a')
    console.log(data1)

    let data2 = await getPromise('b')
    console.log(data2)
}

readFile()

```

`async`函数内部的异常可以通过 `.catch()`或者 `try`/`catch`来捕获,区别是

try/catch 能捕获所有异常,try语句抛出错误后会执行catch语句，try语句内后面的内容不会执行

`catch()`只能捕获异步方法中reject错误，并且catch语句之后的语句会继续执行

```

3.async函数错误捕获，以登录功能为例
      async function getCatch () {
        await new Promise(function (resolve, reject) {
          reject(new Error('登录失败'))
        }).catch(error => {
          console.log(error)  // .catch（）能捕获到错误信息
        })
        console.log('登录成功') //  但是成功信息也会执行
      }
      
     async function getCatch () {
        try {
          await new Promise(function (resolve, reject) {
            reject(new Error('登录失败'))
          })
          console.log('登录成功')  // try抛出错误之后，就不会执行这条语句
        } catch (error) {
          console.log(error)  //  catch语句能捕获到错误信息
        }
      }
```

