# Promise 的进阶

[TOC]

### 如何改变 Promise 对象的状态

可以通过`resolve(),reject()`函数，这是比较常见的两种改变 promise 对象状态的方法

```
    // 第一种,调用resolve函数
    resolve('ok')//pending->fulfilled
    // 第二种,调用rejected函数
    reject('err')//pending->rejected
```

还有第三种，可以抛出一个错误`throw err`

```
    // 第三种,抛出错误
    throw 'err'
```

### promise 指定多个回调的情况

当 promise 指定多个回调函数时，只要是对应它改变状态的回调函数都会被执行

```
  // promise指定多个成功或者失败的回调函数
  let p=new Promise((resolve,reject)=>{
    resolve('ok')
  })
  // 指定回调
  p.then(value=>{
    console.log(value)
  })
  p.then(value=>{
    console.log(value)
  })
  // ok ok
```

如果指定的回调没有对应状态时就不会被执行

```
  p.then(value=>{
  },reason=>{
    console.log(reason)//不会输出
  })
```

### _promise 改变状态和指定回调函数的执行顺序_

一般情况下是执行器中的`resolve()`或者`reject()`先执行，然后再执行`then()`方法

```
    // 一般情况
    let p=new Promise((resolve,reject)=>{
      resolve('ok')
    })
    p.then(value=>{
      console.log(value)
    },reason=>{
      console.log(reaso
```

大多数情况下执行器中的`resolve()`和`reject()`都是放到异步函数中去调用的，这种情况下就是`then()`方法先被执行，然后在执行`resolve()`或者`reject()`

```
    // 构造器中调用的是一个异步
    let p=new Promise((resolve,reject)=>{
      setTimeout(()=>{
        resolve('ok')
      },1000)
    })
    p.then(value=>{
      console.log(value)
    },reason=>{
      console.log(reason);
    })
```

##### 先改变状态再指定回调

第一种可以是普通的 promise 调用，然后调用 then()方法

第二种当改变状态的方法在异步函数中执行，then()方法的调用可以也放到异步函数中执行，延迟的时间比`resolve()`或者是`reject()`要久

```
    // 异步情况下后调用then
    let p=new Promise((resolve,reject)=>{
      setTimeout(()=>{
        resolve('ok')
      },1000)
    })
    setTimeout(()=>{
      p.then(value=>{
      console.log(value)
    },reason=>{
      console.log(reason);
    })
    },2000)
```

##### 先指定回调后改变状态

改变状态的方法在异步函数中去执行。

##### then()方法的执行

如果先改变状态后指定回调，那么`then()`方法就在指定回调之后就被调用。

如果先指定回调再去改变状态，那么`then()`方法就在改变状态后去被调用。

### then()方法

```
   let p = new Promise((resolve, reject) => {
      resolve("ok");
    });
    let res = p.then(
      (value) => {
        console.log(value);
      },
      (reason) => {
        console.log(reason);
      }
    );

    console.log(res);
    // Promise[[Prototype]]: Promisecatch: ƒ catch()constructor: ƒ Promise()finally: ƒ finally()then: ƒ then()Symbol(Symbol.toStringTag): "Promise"[[Prototype]]: Object[[PromiseState]]: "fulfilled"[[PromiseResult]]: undefined
```

then()方法返回的是一个 promise 对象，它返回的 promise 的结果由执行的回调函数来决定。

回调函数返回的是一个异常，promise 对象的结果为失败。

```
//1.返回的是一个异常
throw'err'
//[[PromiseState]]: "rejected"
//[[PromiseResult]]: "err"
```

回调函数返回的是一个非 promise 对象的值，对象的结果为成功。

```
        // 2.返回非promise的值
        return 1123;
        // [[PromiseState]]: "fulfilled"
        // [[PromiseResult]]: 1123
```

回调返回的是一个 promise 对象，对象的结果取决于返回的 promise 的结果

```
 //返回的是失败
          reject();
          // [[PromiseState]]: "rejected"
          // [[PromiseResult]]: undefined

          // 返回的是成功
          resolve();
          // [[PromiseState]]: "fulfilled"
          // [[PromiseResult]]: undefined
```

##### `then()`方法的链式调用

```js
// then()方法的链式使用
let p = new Promise((resolve, reject) => {
  resolve("ok");
});
p.then((value) => {
  return new Promise((resolve, reject) => {
    resolve("success");
  });
}).then((value) => {
  console.log(value);
});
//success
```

先定义了一个 promise 对象并调用 resolve,成功的结果为`ok`,然后在它之后进行`then`方法的回调指定，回调指定中又返回了一个新的 promise 对象并发送成功的结果为`success`,所以在下一个`then`方法的链式回调中输出的成功结果为第二个 promise 的成功结果 success。
如果在后面继续链式调用 then()方法，那么返回的结果为 undefined，因为前面没有调用 resolve 或者是 reject 来指定 promise 的结果，所以 then()方法的调用不会取得成功或者失败的结果。

##### `then()`方法的异常穿透

异常的穿透指的是在链式调用`then()`方法时，可以不在每一个 then()方法中都指定失败的回调，只需要在最后指定失败的回调，`catch()`就可以了。

```js
// then()方法的异常穿透
let p = new Promise((resolve, reject) => {
  // resolve('ok')
  reject("err");
});
p.then((value) => {
  console.log(111);
})
  .then((value) => {
    console.log(222);
  })
  .then((value) => {
    console.log(333);
  })
  .catch((reason) => {
    console.log(reason);
  });
// 成功时执行的结果为111,222,333
// 失败时的结果为err
```
可以看到成功时的每一个then()方法的指定回调都正常执行了，但是在失败时就直接调用末尾的`catch()`方法输出失败的原因。
如果在其中的then()方法中抛出异常，那么就会直接输出这个抛出的异常.
```js
p.then((value) => {
  console.log(111);
})
  .then((value) => {
    throw 'err'
  })
  .then((value) => {
    console.log(333);
  })
  .catch((reason) => {
    console.log(reason);
  });
```
输出的结果为`111 err`，说明执行到第二个then()方法时抛出了错误。直接调用了catch来捕获错误 

##### `then()`链式调用的中断
中断promise的`then()`方法的链式调用只有一种方法，就是在想要中断的then()方法中返回一个pending状态的promise对象。
```js
p.then((value) => {
  console.log(111);
  return new Promise(()=>{})
})
  .then((value) => {
    throw 'err'
  })
  .then((value) => {
    console.log(333);
  })
  .catch((reason) => {
    console.log(reason);
  });
```
因为then()方法返回的就是一个promise的对象，如果返回的promise对象的状态为pending时，那么后面的回调函数就都不会执行了。